<?xml version="1.0"?>

<robot xmlns:xacro="http://www.ros.org/wiki/xacro">

    <xacro:include filename="inertial_macros.xacro" />

    <xacro:if value="$(arg sim_mode)">
        <xacro:include filename="$(find ros2_livox_simulation)/urdf/mid360.xacro" />
    </xacro:if>
    
    <xacro:property name="PI" value="3.1415926"/>


    <link name="base_link">
        <inertial>
            <origin xyz="0 0 0" rpy="0 0 0"/>
            <mass value="1"/>
            <inertia ixx="0.1" ixy="0.1" ixz="0.1" iyy="0.1" iyz="0" izz="0.1"/>
        </inertial>
    </link>

    <joint name="joint_chassis" type="fixed">
        <origin xyz="0 0 0" rpy="0 0 0"/>
        <parent link="base_link"/>
        <child link="chassis"/>
    </joint>

    <link name='base_footprint'>
    </link>

    <joint name="joint_base_footprint" type="fixed">
        <origin xyz="0 0 0" rpy="0 0 -1.57"/>
        <parent link="base_link"/>
        <child link="base_footprint"/>
    </joint>


    <link name="chassis">
        <visual>
            <origin xyz="0 0 -0.025" rpy="0 0 0"/>
            <geometry>
                <!--
                <mesh filename="package://crawler/meshes/chassis.dae" scale="1 1 1" />
                -->
                <box size="0.4 0.4 0.05"/>
            </geometry>
            <material name="Gray">
                <color rgba="0.5 0.5 0.5 1.0"/>
            </material>
        </visual>
        <inertial>
            <origin xyz="0 0 0" rpy="0 0 0"/>
            <mass value="1"/>
            <inertia ixx="0.1" ixy="0" ixz="0" iyy="0.1" iyz="0" izz="0.1"/>
        </inertial>
        <collision>
            <origin xyz="0 0 0" rpy="0 0 0"/>
            <geometry>
                <box size="0.4 0.4 0.05"/>
            </geometry>
        </collision>
    </link>

    <joint name="joint_front_left_wheel" type="continuous">
        <origin xyz="0.19 -0.2 0" rpy="0 0 0"/>
        <parent link="chassis"/>
        <child link="front_left_wheel"/>
        <axis xyz="1 0 0"/>
        <mimic joint="joint_center_left_wheel" multiplier="1" offset="0"/>
    </joint>

    
    <joint name="joint_center_left_wheel" type="continuous">
        <parent link="chassis"/>
        <child link="center_left_wheel"/>
        <origin xyz="0.19 0 0" rpy="0 0 0"/>
        <axis xyz="1 0 0"/>
    </joint>
    
    <joint name="joint_back_left_wheel" type="continuous">
        <origin xyz="0.19 0.2 0" rpy="0 0 0"/>
        <parent link="chassis"/>
        <child link="back_left_wheel"/>
        <axis xyz="1 0 0"/>
        <mimic joint="joint_center_left_wheel" multiplier="1" offset="0"/>
    </joint>

    <xacro:property name="wheel_r" value="0.0652"/>
    <xacro:property name="wheel_l" value="0.03"/>

    <link name="front_left_wheel">
        <visual>
            <origin xyz="0 0 0" rpy="0 ${3.141/2} 0"/>
            <geometry>
                <cylinder radius="${wheel_r}" length="${wheel_l}"/>
            </geometry>
        </visual>
        <collision>
            <origin xyz="0 0 0" rpy="0 ${3.141/2} 0"/>
            <geometry>
                <cylinder radius="${wheel_r}" length="${wheel_l}"/>
            </geometry>
        </collision>
        <xacro:inertial_cylinder mass="0.1" radius="${wheel_r}" length="${wheel_l}">
            <origin xyz="0 0 0" rpy="0 0 0"/>
        </xacro:inertial_cylinder>
    </link>
    <link name="center_left_wheel">
        <visual>
            <origin xyz="0 0 0" rpy="0 ${3.141/2} 0"/>
            <geometry>
                <cylinder radius="${wheel_r}" length="${wheel_l}"/>
            </geometry>
        </visual>
        <collision>
            <origin xyz="0 0 0" rpy="0 ${3.141/2} 0"/>
            <geometry>
                <cylinder radius="${wheel_r}" length="${wheel_l}"/>
            </geometry>
        </collision>
        <xacro:inertial_cylinder mass="0.1" radius="${wheel_r}" length="${wheel_l}">
            <origin xyz="0 0 0" rpy="0 0 0"/>
        </xacro:inertial_cylinder>
    </link>

    <link name="back_left_wheel">
        <visual>
            <origin xyz="0 0 0" rpy="0 ${3.141/2} 0"/>
            <geometry>
                <cylinder radius="${wheel_r}" length="${wheel_l}"/>
            </geometry>
        </visual>
        <collision>
            <origin xyz="0 0 0" rpy="0 ${3.141/2} 0"/>
            <geometry>
                <cylinder radius="${wheel_r}" length="${wheel_l}"/>
            </geometry>
        </collision>
        <xacro:inertial_cylinder mass="0.1" radius="${wheel_r}" length="${wheel_l}">
            <origin xyz="0 0 0" rpy="0 0 0"/>
        </xacro:inertial_cylinder>
    </link>

    <joint name="joint_front_right_wheel" type="continuous">
        <origin xyz="-0.19 -0.2 0" rpy="0 0 0"/>
        <parent link="chassis"/>
        <child link="front_right_wheel"/>
        <axis xyz="1 0 0"/>
        <mimic joint="joint_center_right_wheel" multiplier="1" offset="0"/>\
    </joint>

    <joint name="joint_center_right_wheel" type="continuous">
        <origin xyz="-0.19 0 0" rpy="0 0 0"/>
        <parent link="chassis"/>
        <child link="center_right_wheel"/>
        <axis xyz="1 0 0"/>
    </joint>
  
    <joint name="joint_back_right_wheel" type="continuous">
        <origin xyz="-0.19 0.2 0" rpy="0 0 0"/>
        <parent link="chassis"/>
        <child link="back_right_wheel"/>
        <axis xyz="1 0 0"/>
        <mimic joint="joint_center_right_wheel" multiplier="1" offset="0"/>
    </joint>


    <link name="front_right_wheel">
        <visual>
            <origin xyz="0 0 0" rpy="0 ${3.141/2} 0"/>
            <geometry>
                <cylinder radius="${wheel_r}" length="${wheel_l}"/>
            </geometry>
        </visual>
        <collision>
            <origin xyz="0 0 0" rpy="0 ${3.141/2} 0"/>
            <geometry>
                <cylinder radius="${wheel_r}" length="${wheel_l}"/>
            </geometry>
        </collision>
        <xacro:inertial_cylinder mass="0.1" radius="${wheel_r}" length="${wheel_l}">
            <origin xyz="0 0 0" rpy="0 0 0"/>
        </xacro:inertial_cylinder>
    </link>
    <link name="center_right_wheel">
        <visual>
            <origin xyz="0 0 0" rpy="0 ${3.141/2} 0"/>
            <geometry>
                <cylinder radius="${wheel_r}" length="${wheel_l}"/>
            </geometry>
        </visual>
        <collision>
            <origin xyz="0 0 0" rpy="0 ${3.141/2} 0"/>
            <geometry>
                <cylinder radius="${wheel_r}" length="${wheel_l}"/>
            </geometry>
        </collision>
        <xacro:inertial_cylinder mass="0.1" radius="${wheel_r}" length="${wheel_l}">
            <origin xyz="0 0 0" rpy="0 0 0"/>
        </xacro:inertial_cylinder>
    </link>
    <link name="back_right_wheel">
        <visual>
            <origin xyz="0 0 0" rpy="0 ${3.141/2} 0"/>
            <geometry>
                <cylinder radius="${wheel_r}" length="${wheel_l}"/>
            </geometry>
        </visual>
        <collision>
            <origin xyz="0 0 0" rpy="0 ${3.141/2} 0"/>
            <geometry>
                <cylinder radius="${wheel_r}" length="${wheel_l}"/>
            </geometry>
        </collision>
        <xacro:inertial_cylinder mass="0.1" radius="${wheel_r}" length="${wheel_l}">
            <origin xyz="0 0 0" rpy="0 0 0"/>
        </xacro:inertial_cylinder>
    </link>
    

    <xacro:property name="wheel_mu" value="0.9"/>
    <xacro:property name="wheel_mu2" value="0.2"/>



    <gazebo reference="back_right_wheel">
        <collision>
            <surface>
                <kp>1000000.0</kp>
                <kd>100.0</kd>
                <min_depth>0.01</min_depth>
                <friction>
                    <ode>
                        <mu>${wheel_mu}</mu>
                        <mu2>${wheel_mu2}</mu2>
                        <fdir1>0 1.0 0</fdir1>
                    </ode>
                </friction>
            </surface>
        </collision>
    </gazebo>
        <gazebo reference="center_right_wheel">
        <collision>
            <surface>
                <kp>1000000.0</kp>
                <kd>100.0</kd>
                <min_depth>0.01</min_depth>
                <friction>
                    <ode>
                        <mu>${wheel_mu}</mu>
                        <mu2>${wheel_mu2}</mu2>
                        <fdir1>0 1.0 0</fdir1>
                    </ode>
                </friction>
            </surface>
        </collision>
    </gazebo>
        <gazebo reference="front_right_wheel">
        <collision>
            <surface>
                <kp>1000000.0</kp>
                <kd>100.0</kd>
                <min_depth>0.01</min_depth>
                <friction>
                    <ode>
                        <mu>${wheel_mu}</mu>
                        <mu2>${wheel_mu2}</mu2>
                        <fdir1>0 1.0 0</fdir1>

                    </ode>
                </friction>
            </surface>
        </collision>
    </gazebo>    
    <gazebo reference="back_left_wheel">
        <collision>
            <surface>
                <kp>1000000.0</kp>
                <kd>100.0</kd>
                <min_depth>0.01</min_depth>
                <friction>
                    <ode>
                        <mu>${wheel_mu}</mu>
                        <mu2>${wheel_mu2}</mu2>
                        <fdir1>0 1.0 0</fdir1>
                    </ode>
                </friction>
            </surface>
        </collision>
    </gazebo>
        <gazebo reference="center_left_wheel">
        <collision>
            <surface>
                <min_depth>0.01</min_depth>
                <kp>1000000.0</kp>
                <kd>100.0</kd>
                <friction>
                    <ode>
                        <mu>${wheel_mu}</mu>
                        <mu2>${wheel_mu2}</mu2>
                        <fdir1>0 1.0 0</fdir1>
                    </ode>
                </friction>
            </surface>
        </collision>
    </gazebo>
        <gazebo reference="front_left_wheel">
        <collision>
            <surface>
                <kp>1000000.0</kp>
                <kd>100.0</kd>
                <min_depth>0.01</min_depth>
                <friction>
                    <ode>
                        <mu>${wheel_mu}</mu>
                        <mu2>${wheel_mu2}</mu2>
                        <fdir1>0 1.0 0</fdir1>
                    </ode>
                </friction>
            </surface>
        </collision>
    </gazebo>


    <xacro:if value="$(arg sim_mode)">    
        <xacro:mid360 name="livox" parent="base_link" topic="livox/lidar">
            <!--
            <origin xyz="0 0 0.1" rpy="0 0 -1.57"/>
            -->
            <origin xyz="0 0 0.1" rpy="0 0 0"/>
        </xacro:mid360>
    </xacro:if>


  <joint name="imu_joint" type="fixed">
        <parent link="chassis"/>
        <child link="imu"/>
        <origin xyz="0.055 0 0.175" rpy="0 0 0"/>
    </joint>

    <link name="imu">
        <visual>
            <geometry>
                <box size="0.03 0.03 0.03"/>
            </geometry>
           
        </visual>
    </link>

  <gazebo reference="imu">
    <gravity>true</gravity>
    <sensor name="imu_sensor" type="imu">
      <always_on>true</always_on>
      <update_rate>100</update_rate>
      <visualize>true</visualize>
      <topic>default_topic</topic>
      <plugin filename="libgazebo_ros_imu_sensor.so" name="imu_plugin">
        <topicName>imu</topicName>
        <bodyName>imu</bodyName>
        <updateRateHZ>10.0</updateRateHZ>
        <gaussianNoise>0.0</gaussianNoise>
        <xyzOffset>0 0 0</xyzOffset>
        <rpyOffset>0 0 0</rpyOffset>
        <frameName>imu</frameName>
        <initial_orientation_as_reference>false</initial_orientation_as_reference>
      </plugin>
      <pose>0 0 0 0 0 0</pose>
    </sensor>
  </gazebo>

    <link name="laser_frame">
        
    </link>

    <joint name="laser_joint" type="fixed">
        <parent link="chassis"/>
        <child link="laser_frame"/>
        <origin xyz="0.1 0 0.1" rpy="0 0 0"/>
    </joint>

    <link name="camera_link">
        <visual>
            <geometry>
                <box size="0.1 0.1 0.1"/>
            </geometry>
        </visual>
    </link>

    <joint name="camera_joint" type="fixed">
        <parent link="chassis"/>
        <child link="camera_link"/>
        <origin xyz="0.1 0 0.2" rpy="0 0 0"/>
    </joint>

    <gazebo reference="camera_link">
      <sensor name="camera" type="depth">
          <pose> 0 0 0 0 0 0 </pose>
        <visualize>true</visualize>
        <update_rate>10</update_rate>
        <camera>
            <horizontal_fov>1.089</horizontal_fov>
            <image>
                <format>R8G8B8</format>
                <width>640</width>
                <height>480</height>
            </image>
            <clip>
                <near>0.05</near>
                <far>8.0</far>
            </clip>
        </camera>
    <plugin name="camera_controller" filename="libgazebo_ros_camera.so">
    </plugin>
    </sensor>
    </gazebo>
</robot>